<?xml version="1.0" ?>
<!-- =================================================================================== -->
<!-- |    This document was autogenerated by xacro from myarm_300_pi_thorgripper.urdf  | -->
<!-- |    EDITING THIS FILE BY HAND IS NOT RECOMMENDED                                 | -->
<!-- =================================================================================== -->
<robot name="myarm_300_pi_thorgripper">
  
  <!-- Links definitions -->
  
  <link name="base">
    <visual>
      <geometry>
        <mesh filename="../meshes/base.dae"/>
      </geometry>
      <origin rpy=" 0 0 0" xyz="0.0 0 0 "/>
    </visual>
    <collision>
      <geometry>
        <mesh filename="../meshes/base.dae"/>
      </geometry>
      <origin rpy=" 0 0 0" xyz="0.0 0 0 "/>
    </collision>
  </link>
  
  <link name="link1">
    <visual>
      <geometry>
        <mesh filename="../meshes/j1.dae"/>
      </geometry>
      <origin rpy=" 0 0 0" xyz="0.0 0 -0.086 "/>
    </visual>
    <collision>
      <geometry>
        <mesh filename="../meshes/j1.dae"/>
      </geometry>
      <origin rpy=" 0 0 0" xyz="0.0 0 -0.086 "/>
    </collision>
  </link>
  
  <link name="link2">
    <visual>
      <geometry>
        <mesh filename="../meshes/j2.dae"/>
      </geometry>
      <origin rpy=" 3.14159 0 -1.5708 " xyz="0.0 0 0.0 "/>
    </visual>
    <collision>
      <geometry>
        <mesh filename="../meshes/j2.dae"/>
      </geometry>
      <origin rpy=" 3.14159 0 -1.5708" xyz="0.0 0 0.0 "/>
    </collision>
  </link>
  
  <link name="link3">
    <visual>
      <geometry>
        <mesh filename="../meshes/j3.dae"/>
      </geometry>
      <origin rpy=" 0 0 0" xyz="0.0 0 -0.056 "/>
    </visual>
    <collision>
      <geometry>
        <mesh filename="../meshes/j3.dae"/>
      </geometry>
      <origin rpy=" 0 0 0" xyz="0.0 0 -0.056"/>
    </collision>
  </link>
  
  <link name="link4">
    <visual>
      <geometry>
        <mesh filename="../meshes/j4.dae"/>
      </geometry>
      <origin rpy="0 0 1.5708" xyz="0.0 0.000 0 "/>
    </visual>
    <collision>
      <geometry>
        <mesh filename="../meshes/j4.dae"/>
      </geometry>
      <origin rpy="0 0 1.5708" xyz="0.0 0.000 0 "/>
    </collision>
  </link>
  
  <link name="link5">
    <visual>
      <geometry>
        <mesh filename="../meshes/j5.dae"/>
      </geometry>
      <origin rpy=" 0 0 0" xyz="0 0.00 -0.0525 "/>
    </visual>
    <collision>
      <geometry>
        <mesh filename="../meshes/j5.dae"/>
      </geometry>
      <origin rpy=" 0 0 0" xyz="0 0.00 -0.0525 "/>
    </collision>
  </link>
  
  <link name="link6">
    <visual>
      <geometry>
        <mesh filename="../meshes/j6.dae"/>
      </geometry>
      <origin rpy=" 0 0 1.5708" xyz="0.0 0.000 -0.0 "/>
    </visual>
    <collision>
      <geometry>
        <mesh filename="../meshes/j6.dae"/>
      </geometry>
      <origin rpy=" 0 0 1.5708" xyz="0.0 0.000 -0.0 "/>
    </collision>
  </link>
  
  <link name="link7">
    <visual>
      <geometry>
        <mesh filename="../meshes/j7.dae"/>
      </geometry>
      <origin rpy=" 0 0 0" xyz="0.0002 -0.0002 -0.0185 "/>
    </visual>
    <collision>
      <geometry>
        <mesh filename="../meshes/j7.dae"/>
      </geometry>
      <origin rpy=" 0 0 0" xyz="0.0002 -0.0002 -0.0185 "/>
    </collision>
  </link>
    
  <link name="flange">
    <visual>
      <geometry>
        <mesh filename="../meshes/flange.dae" scale="1.0 1.0 1.0"/>
      </geometry>
      <origin rpy="0 0 0" xyz="0 0 0"/>
    </visual>
    <collision>
      <geometry>
        <mesh filename="../meshes/flange.dae" scale="1.0 1.0 1.0"/>
      </geometry>
      <origin rpy="0 0 0" xyz="0 0 0"/>
    </collision>
  </link>

  <link name="gripper_base">
    <inertial>
      <origin rpy="0 0 0" xyz="0 0 0"/>
      <mass value="1.0"/>
      <inertia ixx="1.0" ixy="0.0" ixz="0.0" iyy="1.0" iyz="0.0" izz="1.0"/>
    </inertial>
    <visual>
      <origin rpy="0 0 0" xyz="0 0 0"/>
      <geometry>
        <mesh filename="../meshes/GripperBase.dae"/>
      </geometry>
    </visual>
    <collision>
      <origin rpy="0 0 0" xyz="0 0 0.0275"/>
      <geometry>
        <box size="0.065 0.0348 0.055"/>
      </geometry>
    </collision>
    <collision>
      <origin rpy="0 0 0" xyz="-0.004250 0.03125 0.0325"/>
      <geometry>
        <box size="0.0406 0.0277 0.020"/>
      </geometry>
    </collision>
  </link>
  
  <link name="gripper_mid_point">
    <inertial>
      <origin rpy="0 0 0" xyz="0 0 0"/>
      <mass value="1.0"/>
      <inertia ixx="1.0" ixy="0.0" ixz="0.0" iyy="1.0" iyz="0.0" izz="1.0"/>
    </inertial>
  </link>
  <link name="gripper_arm_gear_right">
    <inertial>
      <origin rpy="0 0 0" xyz="0 0 0"/>
      <mass value="1.0"/>
      <inertia ixx="1.0" ixy="0.0" ixz="0.0" iyy="1.0" iyz="0.0" izz="1.0"/>
    </inertial>
    <visual>
      <origin rpy="0 -1.570796326795 1.570796326795" xyz="0 0 0"/>
      <geometry>
        <mesh filename="../meshes/GripperArmGear.dae"/>
      </geometry>
    </visual>
    <collision>
      <origin rpy="0 0 0" xyz="0.0175 -0.0025 0.0"/>
      <geometry>
        <box size="0.035 0.005 0.004"/>
      </geometry>
    </collision>
  </link>
  
  <link name="gripper_arm_gear_left">
    <inertial>
      <origin rpy="0 0 0" xyz="0 0 0"/>
      <mass value="1.0"/>
      <inertia ixx="1.0" ixy="0.0" ixz="0.0" iyy="1.0" iyz="0.0" izz="1.0"/>
    </inertial>
    <visual>
      <origin rpy="0 1.570796326795 -1.570796326795" xyz="0 0 0"/>
      <geometry>
        <mesh filename="../meshes/GripperArmGear.dae"/>
      </geometry>
    </visual>
    <collision>
      <origin rpy="0 0 0" xyz="-0.0175 -0.0025 0.0"/>
      <geometry>
        <box size="0.035 0.005 0.004"/>
      </geometry>
    </collision>
  </link>
  
  <link name="gripper_arm_simple_right">
    <inertial>
      <origin rpy="0 0 0" xyz="0 0 0"/>
      <mass value="1.0"/>
      <inertia ixx="1.0" ixy="0.0" ixz="0.0" iyy="1.0" iyz="0.0" izz="1.0"/>
    </inertial>
    <visual>
      <origin rpy="0 -1.570796326795 1.570796326795" xyz="0 0 0"/>
      <geometry>
        <mesh filename="../meshes/GripperArm.dae"/>
      </geometry>
    </visual>
    <collision>
      <origin rpy="0 0 0" xyz="0.0175 -0.0025 0.0"/>
      <geometry>
        <box size="0.035 0.005 0.004"/>
      </geometry>
    </collision>
  </link>
  
  <link name="gripper_arm_simple_left">
    <inertial>
      <origin rpy="0 0 0" xyz="0 0 0"/>
      <mass value="1.0"/>
      <inertia ixx="1.0" ixy="0.0" ixz="0.0" iyy="1.0" iyz="0.0" izz="1.0"/>
    </inertial>
    <visual>
      <origin rpy="0 1.570796326795 -1.570796326795" xyz="0 0 0"/>
      <geometry>
        <mesh filename="../meshes/GripperArm.dae"/>
      </geometry>
    </visual>
    <collision>
      <origin rpy="0 0 0" xyz="-0.0175 -0.0025 0.0"/>
      <geometry>
        <box size="0.035 0.005 0.004"/>
      </geometry>
    </collision>
  </link>
  
  <link name="gripper_finger_right">
    <inertial>
      <origin rpy="0 0 0" xyz="0 0 0"/>
      <mass value="1.0"/>
      <inertia ixx="1.0" ixy="0.0" ixz="0.0" iyy="1.0" iyz="0.0" izz="1.0"/>
    </inertial>
    <visual>
      <origin rpy="0 0 0" xyz="0 0 0"/>
      <geometry>
        <mesh filename="../meshes/GripperFinger.dae"/>
      </geometry>
    </visual>
    <collision>
      <origin rpy="0 0 0" xyz="0.00525 0.026 0.00775"/>
      <geometry>
        <box size="0.0185 0.06 0.0155"/>
      </geometry>
    </collision>
  </link>
  
  <link name="gripper_finger_left">
    <inertial>
      <origin rpy="0 0 0" xyz="0 0 0"/>
      <mass value="1.0"/>
      <inertia ixx="1.0" ixy="0.0" ixz="0.0" iyy="1.0" iyz="0.0" izz="1.0"/>
    </inertial>
    <visual>
      <origin rpy="0 0 0" xyz="0 0 0"/>
      <geometry>
        <mesh filename="../meshes/GripperFinger.dae"/>
      </geometry>
    </visual>
    <collision>
      <origin rpy="0 0 0" xyz="0.00525 0.026 0.00775"/>
      <geometry>
        <box size="0.0185 0.06 0.0155"/>
      </geometry>
    </collision>
  </link>
  
  <!-- Joints definitions -->
  
  <joint name="joint1" type="revolute">
    <axis xyz="0 0 1"/>
    <limit effort="1000.0" lower="-2.7925" upper="2.7925" velocity="0"/>
    <parent link="base"/>
    <child link="link1"/>
    <origin rpy="0 0 0" xyz="0 0 0.1695"/>
  </joint>
  
  <joint name="joint2" type="revolute">
    <axis xyz="0 0 1"/>
    <limit effort="1000.0" lower="-1.2217" upper="2.0071" velocity="0"/>
    <parent link="link1"/>
    <child link="link2"/>
    <!-- <origin xyz= "0 0  0" rpy = "1.5708 3.14159 0"/>   -->
    <origin rpy="-1.5708 0 0" xyz="0 0  0"/>
  </joint>
  
  <joint name="joint3" type="revolute">
    <axis xyz=" 0 0 1"/>
    <limit effort="1000.0" lower="-2.9670" upper="2.9670" velocity="0"/>
    <parent link="link2"/>
    <child link="link3"/>
    <origin rpy="1.5708 0 0" xyz="0 -0.1155 0   "/>
  </joint>
  
  <joint name="joint4" type="revolute">
    <axis xyz=" 0 0 1"/>
    <limit effort="1000.0" lower="-1.9722" upper="1.3089" velocity="0"/>
    <parent link="link3"/>
    <child link="link4"/>
    <origin rpy="1.5708 0 0" xyz="0.0 0 0.0"/>
  </joint>
  
  <joint name="joint5" type="revolute">
    <axis xyz="0 0 1"/>
    <limit effort="1000.0" lower="-2.9670" upper="2.9670" velocity="0"/>
    <parent link="link4"/>
    <child link="link5"/>
    <origin rpy="-1.5708 0 0" xyz="0 0.1278 0"/>
  </joint>
  
  <joint name="joint6" type="revolute">
    <axis xyz="0 0 1"/>
    <limit effort="1000.0" lower="-2.0071" upper="2.0071" velocity="0"/>
    <parent link="link5"/>
    <child link="link6"/>
    <origin rpy="1.5708 0 0" xyz="0 0.0 0"/>
  </joint>
  
  <joint name="joint7" type="revolute">
    <axis xyz="0 0 1"/>
    <limit effort="1000.0" lower="-3.14159" upper="3.14159" velocity="0"/>
    <parent link="link6"/>
    <child link="link7"/>
    <origin rpy="-1.5708 0 0" xyz="0 0.066 0"/>
  </joint>

  <joint name="link7_to_flange" type="fixed">
    <parent link="link7"/>
    <child link="flange"/>
    <origin rpy="0 0 1.5708" xyz="0 0 0"/>
  </joint>

  <joint name="flange_to_gripper_base" type="fixed">
    <parent link="flange"/>
    <child link="gripper_base"/>
    <origin rpy="0 0 0" xyz="0 0 0"/>
  </joint>
  
  <joint name="gripperbase_to_midpoint" type="fixed">
    <parent link="gripper_base"/>
    <child link="gripper_mid_point"/>
    <origin rpy="0 0 0" xyz="0 0 0"/>
  </joint>
  
  <joint name="endeffector_gripper" type="revolute">
    <parent link="gripper_base"/>
    <child link="gripper_arm_gear_right"/>
    <origin rpy="0 0 0" xyz="0.0145 0.00275 0.0325"/>
    <axis xyz="0 1 0"/>
    <limit effort="4.0" lower="-1.570796326795" upper="0" velocity="1.0"/>
  </joint>
  
  <joint name="gripperbase_to_armgearleft" type="revolute">
    <parent link="gripper_base"/>
    <child link="gripper_arm_gear_left"/>
    <origin rpy="0 0 0" xyz="-0.0145 0.00275 0.0325"/>
    <axis xyz="0 1 0"/>
    <limit effort="4.0" lower="0" upper="1.570796326795" velocity="1.0"/>
    <mimic joint="endeffector_gripper" multiplier="-1"/>
  </joint>
  
  <joint name="gripperbase_to_armsimpleright" type="revolute">
    <parent link="gripper_base"/>
    <child link="gripper_arm_simple_right"/>
    <origin rpy="0 0 0" xyz="0.006 0.00275 0.051"/>
    <axis xyz="0 1 0"/>
    <limit effort="4.0" lower="-1.570796326795" upper="0" velocity="1.0"/>
    <mimic joint="endeffector_gripper" multiplier="1"/>
  </joint>
  
  <joint name="gripperbase_to_armsimpleleft" type="revolute">
    <parent link="gripper_base"/>
    <child link="gripper_arm_simple_left"/>
    <origin rpy="0 0 0" xyz="-0.006 0.00275 0.051"/>
    <axis xyz="0 1 0"/>
    <limit effort="4.0" lower="0" upper="1.570796326795" velocity="1.0"/>
    <mimic joint="endeffector_gripper" multiplier="-1"/>
  </joint>
  
  <joint name="armgearright_to_fingerright" type="revolute">
    <parent link="gripper_arm_gear_right"/>
    <child link="gripper_finger_right"/>
    <origin rpy="-1.570796326795 3.14159265359 0" xyz="0.035 -0.01023 0"/>
    <axis xyz="0 0 1"/>
    <limit effort="4.0" lower="0" upper="1.570796326795" velocity="1.0"/>
    <mimic joint="endeffector_gripper" multiplier="-1"/>
  </joint>
  
  <joint name="armgearleft_to_fingerleft" type="revolute">
    <parent link="gripper_arm_gear_left"/>
    <child link="gripper_finger_left"/>
    <origin rpy="1.570796326795 0 0" xyz="-0.035 0.005175 0"/>
    <axis xyz="0 0 1"/>
    <limit effort="4.0" lower="0" upper="1.570796326795" velocity="1.0"/>
    <mimic joint="endeffector_gripper" multiplier="-1"/>
  </joint>
  
  <!-- End-effector dummy link -->
  
  <link name="endeffector">
    <!-- No visual or collision needed, just a reference frame -->
  </link>
  <!-- Fixed transform from link7 to end-effector -->
  <joint name="link7_to_endeffector" type="fixed">
    <parent link="link7"/>
    <child link="endeffector"/>
    <origin rpy="0 0 0" xyz="0.0 0.0 0.1"/>
  </joint>
</robot>
