<?xml version="1.0" ?>
<!-- =================================================================================== -->
<!-- |    This document was autogenerated by xacro from myarm_300_pi_rod.urdf          | -->
<!-- |    EDITING THIS FILE BY HAND IS NOT RECOMMENDED                                 | -->
<!-- =================================================================================== -->
<robot name="myarm_300_pi_rod">

  <!-- Links definitions -->

  <link name="base">
    <visual>
      <geometry>
        <mesh filename="meshes/base.dae"/>
      </geometry>
      <origin rpy=" 0 0 0" xyz="0.0 0 0 "/>
    </visual>
    <collision>
      <geometry>
        <mesh filename="meshes/base.dae"/>
      </geometry>
      <origin rpy=" 0 0 0" xyz="0.0 0 0 "/>
    </collision>
  </link>

  <link name="link1">
    <visual>
      <geometry>
        <mesh filename="meshes/j1.dae"/>
      </geometry>
      <origin rpy=" 0 0 0" xyz="0.0 0 -0.086 "/>
    </visual>
    <collision>
      <geometry>
        <mesh filename="meshes/j1.dae"/>
      </geometry>
      <origin rpy=" 0 0 0" xyz="0.0 0 -0.086 "/>
    </collision>
  </link>

  <link name="link2">
    <visual>
      <geometry>
        <mesh filename="meshes/j2.dae"/>
      </geometry>
      <origin rpy=" 3.14159 0 -1.5708 " xyz="0.0 0 0.0 "/>
    </visual>
    <collision>
      <geometry>
        <mesh filename="meshes/j2.dae"/>
      </geometry>
      <origin rpy=" 3.14159 0 -1.5708" xyz="0.0 0 0.0 "/>
    </collision>
  </link>

  <link name="link3">
    <visual>
      <geometry>
        <mesh filename="meshes/j3.dae"/>
      </geometry>
      <origin rpy=" 0 0 0" xyz="0.0 0 -0.056 "/>
    </visual>
    <collision>
      <geometry>
        <mesh filename="meshes/j3.dae"/>
      </geometry>
      <origin rpy=" 0 0 0" xyz="0.0 0 -0.056"/>
    </collision>
  </link>

  <link name="link4">
    <visual>
      <geometry>
        <mesh filename="meshes/j4.dae"/>
      </geometry>
      <origin rpy="0 0 1.5708" xyz="0.0 0.000 0 "/>
    </visual>
    <collision>
      <geometry>
        <mesh filename="meshes/j4.dae"/>
      </geometry>
      <origin rpy="0 0 1.5708" xyz="0.0 0.000 0 "/>
    </collision>
  </link>

  <link name="link5">
    <visual>
      <geometry>
        <mesh filename="meshes/j5.dae"/>
      </geometry>
      <origin rpy=" 0 0 0" xyz="0 0.00 -0.0525 "/>
    </visual>
    <collision>
      <geometry>
        <mesh filename="meshes/j5.dae"/>
      </geometry>
      <origin rpy=" 0 0 0" xyz="0 0.00 -0.0525 "/>
    </collision>
  </link>

  <link name="link6">
    <visual>
      <geometry>
        <mesh filename="meshes/j6.dae"/>
      </geometry>
      <origin rpy=" 0 0 1.5708" xyz="0.0 0.000 -0.0 "/>
    </visual>
    <collision>
      <geometry>
        <mesh filename="meshes/j6.dae"/>
      </geometry>
      <origin rpy=" 0 0 1.5708" xyz="0.0 0.000 -0.0 "/>
    </collision>
  </link>

  <link name="link7">
    <visual>
      <geometry>
        <mesh filename="meshes/j7.dae"/>
      </geometry>
      <origin rpy=" 0 0 0" xyz="0.0002 -0.0002 -0.0185 "/>
    </visual>
    <collision>
      <geometry>
        <mesh filename="meshes/j7.dae"/>
      </geometry>
      <origin rpy=" 0 0 0" xyz="0.0002 -0.0002 -0.0185 "/>
    </collision>
  </link>

  <link name="endeffector">
    <visual>
      <geometry>
        <mesh filename="meshes/rod_end_effector.dae"/>
      </geometry>
      <origin rpy="0 0 0" xyz="0 0 -0.0765"/>
    </visual>
    <collision>
      <geometry>
        <mesh filename="meshes/rod_end_effector.dae"/>
      </geometry>
      <origin rpy="0 0 0" xyz="0 0 -0.0765"/>
    </collision>
  </link>

  <!-- Joints definitions -->

  <joint name="joint1" type="revolute">
    <axis xyz="0 0 1"/>
    <limit effort="1000.0" lower="-2.7925" upper="2.7925" velocity="0"/>
    <parent link="base"/>
    <child link="link1"/>
    <origin rpy="0 0 0" xyz="0 0 0.1695"/>
  </joint>

  <joint name="joint2" type="revolute">
    <axis xyz="0 0 1"/>
    <limit effort="1000.0" lower="-1.2217" upper="2.0071" velocity="0"/>
    <parent link="link1"/>
    <child link="link2"/>
    <!-- <origin xyz= "0 0  0" rpy = "1.5708 3.14159 0"/>   -->
    <origin rpy="-1.5708 0 0" xyz="0 0  0"/>
  </joint>

  <joint name="joint3" type="revolute">
    <axis xyz=" 0 0 1"/>
    <limit effort="1000.0" lower="-2.9670" upper="2.9670" velocity="0"/>
    <parent link="link2"/>
    <child link="link3"/>
    <origin rpy="1.5708 0 0" xyz="0 -0.1155 0   "/>
  </joint>

  <joint name="joint4" type="revolute">
    <axis xyz=" 0 0 1"/>
    <limit effort="1000.0" lower="-1.9722" upper="1.3089" velocity="0"/>
    <parent link="link3"/>
    <child link="link4"/>
    <origin rpy="1.5708 0 0" xyz="0.0 0 0.0"/>
  </joint>

  <joint name="joint5" type="revolute">
    <axis xyz="0 0 1"/>
    <limit effort="1000.0" lower="-2.9670" upper="2.9670" velocity="0"/>
    <parent link="link4"/>
    <child link="link5"/>
    <origin rpy="-1.5708 0 0" xyz="0 0.1278 0"/>
  </joint>

  <joint name="joint6" type="revolute">
    <axis xyz="0 0 1"/>
    <limit effort="1000.0" lower="-2.0071" upper="2.0071" velocity="0"/>
    <parent link="link5"/>
    <child link="link6"/>
    <origin rpy="1.5708 0 0" xyz="0 0.0 0"/>
  </joint>

  <joint name="joint7" type="revolute">
    <axis xyz="0 0 1"/>
    <limit effort="1000.0" lower="-3.14159" upper="3.14159" velocity="0"/>
    <parent link="link6"/>
    <child link="link7"/>
    <origin rpy="-1.5708 0 0" xyz="0 0.066 0"/>
  </joint>

  <joint name="link7_to_endeffector" type="fixed">
    <parent link="link7"/>
    <child link="endeffector"/>
    <origin rpy="0 0 0" xyz="0 0 0.1"/>
  </joint>
</robot>
